Workbook
Name Country: '[1]Country Data'!$A$6:$A$52
Name NPV_Country: '[1]User Inputs'!$F$11

Sheet Instructions
A1: INSTRUCTIONS
A3: Step 1: In the "User Inputs" tab, select the country you are interested in estimating costs and benefits of implementing the Roadmap
A4: Step 2: Data is already pre-populated from the Roadmap Global Investment Case completed in 2019; Adjust as needed any cells in yellow in the "User inputs" tab by revising any values
A5: Step 3: See tab "Summary" for adjusted outputs and estimates on costs and benefits of implementing the Roadmap (note that this tab does not require any adjustments)
A9: OBJECTIVE OF TOOL
A11: This tool was developed using the methodology from the GTFCC Global Investment Case (completed in 2019) to estimate the potential costs and benefits of implementing the Roadmap. The tool has been simplified for country use to provide key inputs into their Country Investment Case to advocate for implementing the interventions of Ending Cholera: A roadmap to 2030. The Country Invesment Case can be used to assist countries to fundraise for different interventions.

Sheet User Inputs
B3: COUNTRY DATA VERIFICATION
C5: Step 1: SELECT COUNTRY --> | F5: Malawi
C7: Step 2: ENTER COUNTRY DATA- Please validate and replace default values with country data if available | I7: ROADMAP DATA SOURCE /COMMENT
C8: OVERVIEW AND TIME | F8: Start | G8: End
E9: Roadmap start and end year | F9: 2026 | G9: 2030 | J9: MMCCP
E10: Time period for Country investment case (in years) | F10: 5
C11: Social discount rate for valuing future costs and benefits in present values (2019) | F11: =INDIRECT("'Country Data'!"&ADDRESS(MATCH($F$5,'Country Data'!$A:$A,FALSE),MATCH(ADDRESS(ROW(),COLUMN(),4),'Country Model'!$9:$9,FALSE),4))+F2 -> 0.05
E12: WASH Target in elimination year | F12: 0.9
C13: BASELINE DATA | F13: Urban | G13: Rural
D14: National population size ('000) | F14: 3234 | G14: 17499 | J14: National Statistic Office 2025 projections (20,270,568) (Applying distribution of population by area of residence for 2020 Integrated Household Survey - 84.4 Rural & 15.6 Urban)
D15: Average population growth until 2030 (% annual) | F15: =INDIRECT("'Country Data'!"&ADDRESS(MATCH($F$5,'Country Data'!$A:$A,FALSE),MATCH(ADDRESS(ROW(),COLUMN(),4),'Country Model'!$9:$9,FALSE),4)) -> 4.2208078 | G15: =INDIRECT("'Country Data'!"&ADDRESS(MATCH($F$5,'Country Data'!$A:$A,FALSE),MATCH(ADDRESS(ROW(),COLUMN(),4),'Country Model'!$9:$9,FALSE),4)) -> 2.3622412
D16: Population age breakdown (3 age groups must add to 100%) | F16: =F17+F18+F19 -> 1 | G16: =G17+G18+G19 -> 1
E17: 0-4 years | F17: 0.13 | G17: 0.15 | J17: Calculations based on the 2018 census National Population tables
E18: 5-14 years | F18: 0.25 | G18: 0.3
E19: 15+ years | F19: 0.62 | G19: 0.55
D20: Average household size (number of members) | F20: 4 | G20: 4.5
D21: Population living in cholera hotspots in Year 0 | F21: 1215861 | G21: 7036077 | J21: PAMI
D22: Water Basic Coverage - Year 0 | F22: 0.52 | G22: 0.58 | J22: 2024/2025 Malawi WASH Budget Brief by UNICEF (Investing in climate-resilient WASH services amidst recurring climatic shocks and vulnerabilities in Malawi)
D23: Sanitation Basic Coverage - Year 0 | F23: 0.07 | G23: 0.02 | J23: The WHO/UNICEF Joint Monitoring Programme (JMP) 2022 Data
D24: Hygiene Basic Coverage - Year 0 | F24: 0.28 | G24: 0.13 | J24: The WHO/UNICEF Joint Monitoring Programme (JMP) 2022 Data
C25: UNIT COSTS - TUBEWELLS
D26: New facility cost (initial cost per person in USD) | F26: 65 | G26: 50 | J26: Expert opinion, Dept. of Water development
D27: New facility life (number of years before replacement) | F27: =INDIRECT("'Country Data'!"&ADDRESS(MATCH($F$5,'Country Data'!$A:$A,FALSE),MATCH(ADDRESS(ROW(),COLUMN(),4),'Country Model'!$9:$9,FALSE),4)) -> 20 | G27: =INDIRECT("'Country Data'!"&ADDRESS(MATCH($F$5,'Country Data'!$A:$A,FALSE),MATCH(ADDRESS(ROW(),COLUMN(),4),'Country Model'!$9:$9,FALSE),4)) -> 20
D28: Water treatment (cost per person per year in USD) | F28: 5 | G28: 5
D29: Water source O&M cost (cost per person per year in USD) | F29: 2.5 | G29: 3
C30: UNIT COSTS - PIT LATRINES
D31: New facility cost (initial cost per person in USD) | F31: 40 | G31: 40
D32: New facility life (number of years before replacement) | F32: =INDIRECT("'Country Data'!"&ADDRESS(MATCH($F$5,'Country Data'!$A:$A,FALSE),MATCH(ADDRESS(ROW(),COLUMN(),4),'Country Model'!$9:$9,FALSE),4)) -> 10 | G32: =INDIRECT("'Country Data'!"&ADDRESS(MATCH($F$5,'Country Data'!$A:$A,FALSE),MATCH(ADDRESS(ROW(),COLUMN(),4),'Country Model'!$9:$9,FALSE),4)) -> 10
D33: O&M cost (cost per person per year in USD) | F33: 5.5 | G33: 5.5
C34: UNIT COSTS - HYGIENE
D35: New handwashing station cost (initial cost per person, US$ 2018 prices) | F35: =INDIRECT("'Country Data'!"&ADDRESS(MATCH($F$5,'Country Data'!$A:$A,FALSE),MATCH(ADDRESS(ROW(),COLUMN(),4),'Country Model'!$9:$9,FALSE),4)) -> 17.499201 | G35: =INDIRECT("'Country Data'!"&ADDRESS(MATCH($F$5,'Country Data'!$A:$A,FALSE),MATCH(ADDRESS(ROW(),COLUMN(),4),'Country Model'!$9:$9,FALSE),4)) -> 3.1001201
D36: New facility life (number of years before replacement) | F36: =INDIRECT("'Country Data'!"&ADDRESS(MATCH($F$5,'Country Data'!$A:$A,FALSE),MATCH(ADDRESS(ROW(),COLUMN(),4),'Country Model'!$9:$9,FALSE),4)) -> 5 | G36: =INDIRECT("'Country Data'!"&ADDRESS(MATCH($F$5,'Country Data'!$A:$A,FALSE),MATCH(ADDRESS(ROW(),COLUMN(),4),'Country Model'!$9:$9,FALSE),4)) -> 5
D37: O&M cost, including soap (cost per person per year, US$ 2018 prices) | F37: =INDIRECT("'Country Data'!"&ADDRESS(MATCH($F$5,'Country Data'!$A:$A,FALSE),MATCH(ADDRESS(ROW(),COLUMN(),4),'Country Model'!$9:$9,FALSE),4)) -> 11.114799 | G37: =INDIRECT("'Country Data'!"&ADDRESS(MATCH($F$5,'Country Data'!$A:$A,FALSE),MATCH(ADDRESS(ROW(),COLUMN(),4),'Country Model'!$9:$9,FALSE),4)) -> 5.3609712
C38: UNIT COSTS - OTHER
D39: Emergency WASH (cost per person receiving emergency WASH) | F39: 10 | G39: 10
D40: National Surveillance Costs (average annual cost from start of roadmap) | F40: 482124 | G40: =INDIRECT("'Country Data'!"&ADDRESS(MATCH($F$5,'Country Data'!$A:$A,FALSE),MATCH(ADDRESS(ROW(),COLUMN(),4),'Country Model'!$9:$9,FALSE),4)) -> #N/A
C41: UNIT COSTS - OCV CAMPAIGNS (Preventive)
D42: Vaccine unit price per dose, after 2025 (in USD) | F42: 2.5 | G42: =INDIRECT("'Country Data'!"&ADDRESS(MATCH($F$5,'Country Data'!$A:$A,FALSE),MATCH(ADDRESS(ROW(),COLUMN(),4),'Country Model'!$9:$9,FALSE),4)) -> #N/A
D43: Doses per person vaccinated | F43: 2 | G43: =INDIRECT("'Country Data'!"&ADDRESS(MATCH($F$5,'Country Data'!$A:$A,FALSE),MATCH(ADDRESS(ROW(),COLUMN(),4),'Country Model'!$9:$9,FALSE),4)) -> #N/A
D44: Vaccine delivery (cost per person receiving required doses, US$ 2025) | F44: 1.25 | G44: 1.25
...

Sheet Summary
A1: Step 3: Summary of the outcomes
A3: =UPPER('User Inputs'!F5 & " CHOLERA INVESTMENT REPORT") -> MALAWI CHOLERA INVESTMENT REPORT
B4: From | C4: ='User Inputs'!$F$9 -> 2026 | D4: to | E4: ='User Inputs'!$F$10+$C$4-1 -> 2030
A6: In USD
A7: All values are rounded | B7: Total | C7: =C4 -> 2026 | D7: =IF(AND(C7+1<=$E$4,C7+1>$C$4),C7+1,0) -> 2027 | E7: =IF(AND(D7+1<=$E$4,D7+1>$C$4),D7+1,0) -> 2028 | F7: =IF(AND(E7+1<=$E$4,E7+1>$C$4),E7+1,0) -> 2029 | G7: =IF(AND(F7+1<=$E$4,F7+1>$C$4),F7+1,0) -> 2030 | H7: =IF(AND(G7+1<=$E$4,G7+1>$C$4),G7+1,0) -> 0 | I7: =IF(AND(H7+1<=$E$4,H7+1>$C$4),H7+1,0) -> 0 | J7: =IF(AND(I7+1<=$E$4,I7+1>$C$4),I7+1,0) -> 0 | K7: =IF(AND(J7+1<=$E$4,J7+1>$C$4),J7+1,0) -> 0 | ... T7: =IF(AND(S7+1<=$E$4,S7+1>$C$4),S7+1,0) -> 0
A8: Estimated costs from implementing the Roadmap (USD) | B8: =ROUND(SUM(C8:U8),-6) -> 335000000 | C8: =IF(C7>2021,HLOOKUP(C$7,Tables!$L$5:$AD$10,Tables!$AG9,FALSE)*-1,"") -> 0 | D8: =IF(D7>2021,HLOOKUP(D$7,Tables!$L$5:$AD$10,Tables!$AG9,FALSE)*-1,"") -> 0 | E8: =IF(E7>2021,HLOOKUP(E$7,Tables!$L$5:$AD$10,Tables!$AG9,FALSE)*-1,"") -> 0 | F8: =IF(F7>2021,HLOOKUP(F$7,Tables!$L$5:$AD$10,Tables!$AG10,FALSE)*-1,"") -> 1.65241e+08 | G8: =IF(G7>2021,HLOOKUP(G$7,Tables!$L$5:$AD$10,Tables!$AG10,FALSE)*-1,"") -> 1.6977448e+08 | H8: =IF(H7>2021,HLOOKUP(H$7,Tables!$L$5:$AD$10,Tables!$AG10,FALSE)*-1,"") | I8: =IF(I7>2021,HLOOKUP(I$7,Tables!$L$5:$AD$10,Tables!$AG10,FALSE)*-1,"") | J8: =IF(J7>2021,HLOOKUP(J$7,Tables!$L$5:$AD$10,Tables!$AG10,FALSE)*-1,"") | K8: =IF(K7>2021,HLOOKUP(K$7,Tables!$L$5:$AD$10,Tables!$AG10,FALSE)*-1,"") | L8: =IF(L7>2021,HLOOKUP(L$7,Tables!$L$5:$AD$10,Tables!$AG10,FALSE)*-1,"") | M8: =IF(M7>2021,HLOOKUP(M$7,Tables!$L$5:$AD$10,Tables!$AG10,FALSE)*-1,"") | ... T8: =IF(T7>2021,HLOOKUP(T$7,Tables!$L$5:$AD$10,Tables!$AG10,FALSE)*-1,"")
A9: Estimated benefits from implementing the Roadmap | B9: =ROUND(SUM(C9:U9),-6) -> 1697000000 | C9: =IF(C7>2021,HLOOKUP(C$7,Tables!$L$5:$AD$20,Tables!$AG20,FALSE),"") -> 82659769 | D9: =IF(D7>2021,HLOOKUP(D$7,Tables!$L$5:$AD$20,Tables!$AG20,FALSE),"") -> 85001360 | E9: =IF(E7>2021,HLOOKUP(E$7,Tables!$L$5:$AD$20,Tables!$AG20,FALSE),"") -> 87414683 | F9: =IF(F7>2021,HLOOKUP(F$7,Tables!$L$5:$AD$22,Tables!$AG22,FALSE),"") -> 7.1265253e+08 | G9: =IF(G7>2021,HLOOKUP(G$7,Tables!$L$5:$AD$22,Tables!$AG22,FALSE),"") -> 7.2934666e+08 | H9: =IF(H7>2021,HLOOKUP(H$7,Tables!$L$5:$AD$22,Tables!$AG22,FALSE),"") | I9: =IF(I7>2021,HLOOKUP(I$7,Tables!$L$5:$AD$22,Tables!$AG22,FALSE),"") | J9: =IF(J7>2021,HLOOKUP(J$7,Tables!$L$5:$AD$22,Tables!$AG22,FALSE),"") | K9: =IF(K7>2021,HLOOKUP(K$7,Tables!$L$5:$AD$22,Tables!$AG22,FALSE),"") | L9: =IF(L7>2021,HLOOKUP(L$7,Tables!$L$5:$AD$22,Tables!$AG22,FALSE),"") | M9: =IF(M7>2021,HLOOKUP(M$7,Tables!$L$5:$AD$22,Tables!$AG22,FALSE),"") | ... T9: =IF(T7>2021,HLOOKUP(T$7,Tables!$L$5:$AD$22,Tables!$AG22,FALSE),"")
A10: Estimated population benefiting from Roadmap interventions | B10: =ROUND(SUM(C10:U10),-6) -> 19000000 | C10: =IF(C7>2021,HLOOKUP(C$7,Tables!$L$5:$AD$31,Tables!$AG30,FALSE),"") -> 0 | D10: =IF(D7>2021,HLOOKUP(D$7,Tables!$L$5:$AD$31,Tables!$AG30,FALSE),"") -> 8878485.7 | E10: =IF(E7>2021,HLOOKUP(E$7,Tables!$L$5:$AD$31,Tables!$AG30,FALSE),"") -> 0 | F10: =IF(F7>2021,HLOOKUP(F$7,Tables!$L$5:$AD$31,Tables!$AG31,FALSE),"") -> 287512.68 | G10: =IF(G7>2021,HLOOKUP(G$7,Tables!$L$5:$AD$31,Tables!$AG31,FALSE),"") -> 9907599.7 | H10: =IF(H7>2021,HLOOKUP(H$7,Tables!$L$5:$AD$31,Tables!$AG31,FALSE),"") | I10: =IF(I7>2021,HLOOKUP(I$7,Tables!$L$5:$AD$31,Tables!$AG31,FALSE),"") | J10: =IF(J7>2021,HLOOKUP(J$7,Tables!$L$5:$AD$31,Tables!$AG31,FALSE),"") | K10: =IF(K7>2021,HLOOKUP(K$7,Tables!$L$5:$AD$31,Tables!$AG31,FALSE),"") | L10: =IF(L7>2021,HLOOKUP(L$7,Tables!$L$5:$AD$31,Tables!$AG31,FALSE),"") | M10: =IF(M7>2021,HLOOKUP(M$7,Tables!$L$5:$AD$31,Tables!$AG31,FALSE),"") | ... T10: =IF(T7>2021,HLOOKUP(T$7,Tables!$L$5:$AD$31,Tables!$AG31,FALSE),"")
A11: Estimated cholera cases averted | B11: =SUM(C11:U11) -> 300309.09 | C11: =IF(C$7>2021,HLOOKUP(C$7,Tables!$L$5:$AD$103,Tables!$AG50,FALSE)-HLOOKUP(C$7,Tables!$L$5:$AD$103,Tables!$AG53,FALSE),"") -> 48760.623 | D11: =IF(D$7>2021,HLOOKUP(D$7,Tables!$L$5:$AD$103,Tables!$AG50,FALSE)-HLOOKUP(D$7,Tables!$L$5:$AD$103,Tables!$AG53,FALSE),"") -> 50137.304 | E11: =IF(E$7>2021,HLOOKUP(E$7,Tables!$L$5:$AD$103,Tables!$AG50,FALSE)-HLOOKUP(E$7,Tables!$L$5:$AD$103,Tables!$AG53,FALSE),"") -> 51555.995 | F11: =IF(F$7>2021,HLOOKUP(F$7,Tables!$L$5:$AD$103,Tables!$AG50,FALSE)-HLOOKUP(F$7,Tables!$L$5:$AD$103,Tables!$AG51,FALSE),"") -> 73877.667 | G11: =IF(G$7>2021,HLOOKUP(G$7,Tables!$L$5:$AD$103,Tables!$AG50,FALSE)-HLOOKUP(G$7,Tables!$L$5:$AD$103,Tables!$AG51,FALSE),"") -> 75977.503 | H11: =IF(H$7>2021,HLOOKUP(H$7,Tables!$L$5:$AD$103,Tables!$AG50,FALSE)-HLOOKUP(H$7,Tables!$L$5:$AD$103,Tables!$AG51,FALSE),"") | I11: =IF(I$7>2021,HLOOKUP(I$7,Tables!$L$5:$AD$103,Tables!$AG50,FALSE)-HLOOKUP(I$7,Tables!$L$5:$AD$103,Tables!$AG51,FALSE),"") | J11: =IF(J$7>2021,HLOOKUP(J$7,Tables!$L$5:$AD$103,Tables!$AG50,FALSE)-HLOOKUP(J$7,Tables!$L$5:$AD$103,Tables!$AG51,FALSE),"") | K11: =IF(K$7>2021,HLOOKUP(K$7,Tables!$L$5:$AD$103,Tables!$AG50,FALSE)-HLOOKUP(K$7,Tables!$L$5:$AD$103,Tables!$AG51,FALSE),"") | L11: =IF(L$7>2021,HLOOKUP(L$7,Tables!$L$5:$AD$103,Tables!$AG50,FALSE)-HLOOKUP(L$7,Tables!$L$5:$AD$103,Tables!$AG51,FALSE),"") | M11: =IF(M$7>2021,HLOOKUP(M$7,Tables!$L$5:$AD$103,Tables!$AG50,FALSE)-HLOOKUP(M$7,Tables!$L$5:$AD$103,Tables!$AG51,FALSE),"") | ... T11: =IF(T$7>2021,HLOOKUP(T$7,Tables!$L$5:$AD$103,Tables!$AG50,FALSE)-HLOOKUP(T$7,Tables!$L$5:$AD$103,Tables!$AG51,FALSE),"")
A12: Estimated cholera deaths averted | B12: =SUM(C12:U12) -> 8746.6177 | C12: =IF(C$7>2021,HLOOKUP(C$7,Tables!$L$5:$AD$103,Tables!$AG57,FALSE)-HLOOKUP(C$7,Tables!$L$5:$AD$103,Tables!$AG60,FALSE),"") -> 1421.5752 | D12: =IF(D$7>2021,HLOOKUP(D$7,Tables!$L$5:$AD$103,Tables!$AG57,FALSE)-HLOOKUP(D$7,Tables!$L$5:$AD$103,Tables!$AG60,FALSE),"") -> 1461.0789 | E12: =IF(E$7>2021,HLOOKUP(E$7,Tables!$L$5:$AD$103,Tables!$AG57,FALSE)-HLOOKUP(E$7,Tables!$L$5:$AD$103,Tables!$AG60,FALSE),"") -> 1501.7657 | F12: =IF(F$7>2021,HLOOKUP(F$7,Tables!$L$5:$AD$103,Tables!$AG57,FALSE)-HLOOKUP(F$7,Tables!$L$5:$AD$103,Tables!$AG58,FALSE),"") -> 2151.0214 | G12: =IF(G$7>2021,HLOOKUP(G$7,Tables!$L$5:$AD$103,Tables!$AG57,FALSE)-HLOOKUP(G$7,Tables!$L$5:$AD$103,Tables!$AG58,FALSE),"") -> 2211.1764 | H12: =IF(H$7>2021,HLOOKUP(H$7,Tables!$L$5:$AD$103,Tables!$AG57,FALSE)-HLOOKUP(H$7,Tables!$L$5:$AD$103,Tables!$AG58,FALSE),"") | I12: =IF(I$7>2021,HLOOKUP(I$7,Tables!$L$5:$AD$103,Tables!$AG57,FALSE)-HLOOKUP(I$7,Tables!$L$5:$AD$103,Tables!$AG58,FALSE),"") | J12: =IF(J$7>2021,HLOOKUP(J$7,Tables!$L$5:$AD$103,Tables!$AG57,FALSE)-HLOOKUP(J$7,Tables!$L$5:$AD$103,Tables!$AG58,FALSE),"") | K12: =IF(K$7>2021,HLOOKUP(K$7,Tables!$L$5:$AD$103,Tables!$AG57,FALSE)-HLOOKUP(K$7,Tables!$L$5:$AD$103,Tables!$AG58,FALSE),"") | L12: =IF(L$7>2021,HLOOKUP(L$7,Tables!$L$5:$AD$103,Tables!$AG57,FALSE)-HLOOKUP(L$7,Tables!$L$5:$AD$103,Tables!$AG58,FALSE),"") | M12: =IF(M$7>2021,HLOOKUP(M$7,Tables!$L$5:$AD$103,Tables!$AG57,FALSE)-HLOOKUP(M$7,Tables!$L$5:$AD$103,Tables!$AG58,FALSE),"") | ... T12: =IF(T$7>2021,HLOOKUP(T$7,Tables!$L$5:$AD$103,Tables!$AG57,FALSE)-HLOOKUP(T$7,Tables!$L$5:$AD$103,Tables!$AG58,FALSE),"")
A13: Estimated diarrhea cases averted | B13: =SUM(C13:U13) -> 1.4083616e+08 | C13: 0 | D13: 0 | E13: 0 | F13: =IF(F$7>2021,HLOOKUP(F$7,Tables!$L$5:$AD$103,Tables!$AG64,FALSE)-HLOOKUP(F$7,Tables!$L$5:$AD$103,Tables!$AG65,FALSE),"") -> 70344951 | G13: =IF(G$7>2021,HLOOKUP(G$7,Tables!$L$5:$AD$103,Tables!$AG64,FALSE)-HLOOKUP(G$7,Tables!$L$5:$AD$103,Tables!$AG65,FALSE),"") -> 70491211 | H13: =IF(H$7>2021,HLOOKUP(H$7,Tables!$L$5:$AD$103,Tables!$AG64,FALSE)-HLOOKUP(H$7,Tables!$L$5:$AD$103,Tables!$AG65,FALSE),"") | I13: =IF(I$7>2021,HLOOKUP(I$7,Tables!$L$5:$AD$103,Tables!$AG64,FALSE)-HLOOKUP(I$7,Tables!$L$5:$AD$103,Tables!$AG65,FALSE),"") | J13: =IF(J$7>2021,HLOOKUP(J$7,Tables!$L$5:$AD$103,Tables!$AG64,FALSE)-HLOOKUP(J$7,Tables!$L$5:$AD$103,Tables!$AG65,FALSE),"") | K13: =IF(K$7>2021,HLOOKUP(K$7,Tables!$L$5:$AD$103,Tables!$AG64,FALSE)-HLOOKUP(K$7,Tables!$L$5:$AD$103,Tables!$AG65,FALSE),"") | L13: =IF(L$7>2021,HLOOKUP(L$7,Tables!$L$5:$AD$103,Tables!$AG64,FALSE)-HLOOKUP(L$7,Tables!$L$5:$AD$103,Tables!$AG65,FALSE),"") | M13: =IF(M$7>2021,HLOOKUP(M$7,Tables!$L$5:$AD$103,Tables!$AG64,FALSE)-HLOOKUP(M$7,Tables!$L$5:$AD$103,Tables!$AG65,FALSE),"") | ... T13: =IF(T$7>2021,HLOOKUP(T$7,Tables!$L$5:$AD$103,Tables!$AG64,FALSE)-HLOOKUP(T$7,Tables!$L$5:$AD$103,Tables!$AG65,FALSE),"")
A14: Estimated diarrhea deaths averted | B14: =SUM(C14:U14) -> 4219.5633 | C14: 0 | D14: 0 | E14: 0 | F14: =IF(F$7>2021,HLOOKUP(F$7,Tables!$L$5:$AD$103,Tables!$AG68,FALSE)-HLOOKUP(F$7,Tables!$L$5:$AD$103,Tables!$AG69,FALSE),"") -> 2079.5574 | G14: =IF(G$7>2021,HLOOKUP(G$7,Tables!$L$5:$AD$103,Tables!$AG68,FALSE)-HLOOKUP(G$7,Tables!$L$5:$AD$103,Tables!$AG69,FALSE),"") -> 2140.0059 | H14: =IF(H$7>2021,HLOOKUP(H$7,Tables!$L$5:$AD$103,Tables!$AG68,FALSE)-HLOOKUP(H$7,Tables!$L$5:$AD$103,Tables!$AG69,FALSE),"") | I14: =IF(I$7>2021,HLOOKUP(I$7,Tables!$L$5:$AD$103,Tables!$AG68,FALSE)-HLOOKUP(I$7,Tables!$L$5:$AD$103,Tables!$AG69,FALSE),"") | J14: =IF(J$7>2021,HLOOKUP(J$7,Tables!$L$5:$AD$103,Tables!$AG68,FALSE)-HLOOKUP(J$7,Tables!$L$5:$AD$103,Tables!$AG69,FALSE),"") | K14: =IF(K$7>2021,HLOOKUP(K$7,Tables!$L$5:$AD$103,Tables!$AG68,FALSE)-HLOOKUP(K$7,Tables!$L$5:$AD$103,Tables!$AG69,FALSE),"") | L14: =IF(L$7>2021,HLOOKUP(L$7,Tables!$L$5:$AD$103,Tables!$AG68,FALSE)-HLOOKUP(L$7,Tables!$L$5:$AD$103,Tables!$AG69,FALSE),"") | M14: =IF(M$7>2021,HLOOKUP(M$7,Tables!$L$5:$AD$103,Tables!$AG68,FALSE)-HLOOKUP(M$7,Tables!$L$5:$AD$103,Tables!$AG69,FALSE),"") | ... T14: =IF(T$7>2021,HLOOKUP(T$7,Tables!$L$5:$AD$103,Tables!$AG68,FALSE)-HLOOKUP(T$7,Tables!$L$5:$AD$103,Tables!$AG69,FALSE),"")
A16: Overall estimated benefit per US dollar invested of implementing Roadmap for the full time period:
A17: ="US$1 invested in the Roadmap results in US$"& ROUND(Tables!AE22/Tables!AE10*-1,0) &" in benefits" -> US$1 invested in the Roadmap results in US$4 in benefits | C17: FIXED TIME PERIOD 2022-2040 ---> Total Benefits / Total Costs (WASH included in all years)
A18: ="US$1 invested in the Roadmap results in US$"& ROUND(B9/B8,0) &" in benefits" -> US$1 invested in the Roadmap results in US$5 in benefits | C18: VARIABLE TIME PERIOD (based on user input) --> Total Benefits / Total Costs time period selected [WASH benefits & costs only included from 2026 onwards]
A20: Assumption
A21: First 3 years, key intervention is OCV to give time to plan and implement WASH

Sheet Tables
D2: -1 | L2: Year 1 | M2: Year 2 | N2: Year 3 | O2: Year 4 | P2: Year 5
D3: WASH Ramp up | L3: 0.1 | M3: 0.3 | N3: 0.5 | O3: 0.75 | P3: 1 | AG3: Hlookup
E5: 2015 | F5: 2016 | G5: 2017 | H5: 2018 | I5: 2019 | J5: 2020 | K5: 2021 | L5: 2022 | M5: 2023 | N5: 2024 | O5: 2025 | P5: 2026 | Q5: 2027 | R5: 2028 | S5: 2029 | T5: 2030 | U5: 2031 | V5: 2032 | W5: 2033 | X5: 2034 | Y5: 2035 | Z5: 2036 | AA5: 2037 | AB5: 2038 | AC5: 2039 | AD5: 2040 | AE5: TOTAL | AG5: 1
B6: 1. Cost - Benefit (NOTE DOES NOT INCLDUE SURVEILLANCE) | AG6: =AG5+1 -> 2
D7: Cost: WASH Capital | E7: =(SUM('Country Model'!E34:E36)+SUM('Country Model'!AE34:AE36))*-1 -> 0 | F7: =(SUM('Country Model'!F34:F36)+SUM('Country Model'!AF34:AF36))*-1 -> 0 | G7: =(SUM('Country Model'!G34:G36)+SUM('Country Model'!AG34:AG36))*-1 -> 0 | H7: =(SUM('Country Model'!H34:H36)+SUM('Country Model'!AH34:AH36))*-1 -> -91852303 | I7: =(SUM('Country Model'!I34:I36)+SUM('Country Model'!AI34:AI36))*-1 -> -91852303 | J7: =(SUM('Country Model'!J34:J36)+SUM('Country Model'!AJ34:AJ36))*-1 -> -91852303 | K7: =(SUM('Country Model'!K34:K36)+SUM('Country Model'!AK34:AK36))*-1 -> -91852303 | L7: =(SUM('Country Model'!L34:L36)+SUM('Country Model'!AL34:AL36))*-1 -> -91852303 | ... AD7: =(SUM('Country Model'!AD34:AD36)+SUM('Country Model'!BD34:BD36))*-1 -> -40244309 | AE7: =SUM(E7:AD7) -> -1.163225e+09 | AG7: =AG6+1 -> 3
D8: Cost: WASH O&M | E8: =(SUM('Country Model'!E38:E40)+SUM('Country Model'!AE38:AE40))*-1 -> 0 | F8: =(SUM('Country Model'!F38:F40)+SUM('Country Model'!AF38:AF40))*-1 -> 0 | G8: =(SUM('Country Model'!G38:G40)+SUM('Country Model'!AG38:AG40))*-1 -> 0 | H8: =(SUM('Country Model'!H38:H40)+SUM('Country Model'!AH38:AH40))*-1 -> -29650577 | I8: =(SUM('Country Model'!I38:I40)+SUM('Country Model'!AI38:AI40))*-1 -> -36866230 | J8: =(SUM('Country Model'!J38:J40)+SUM('Country Model'!AJ38:AJ40))*-1 -> -51761203 | K8: =(SUM('Country Model'!K38:K40)+SUM('Country Model'!AK38:AK40))*-1 -> -67421233 | L8: =(SUM('Country Model'!L38:L40)+SUM('Country Model'!AL38:AL40))*-1 -> -83878351 | ... AD8: =(SUM('Country Model'!AD38:AD40)+SUM('Country Model'!BD38:BD40))*-1 -> -1.8297577e+08 | AE8: =SUM(E8:AD8) -> -2.901719e+09 | AG8: =AG7+1 -> 4
D9: Cost: OCV Campaigns, Surveillance | E9: =('Country Model'!E42+'Country Model'!AE42)*-1 -> 0 | F9: =('Country Model'!F42+'Country Model'!AF42)*-1 -> 0 | G9: =('Country Model'!G42+'Country Model'!AG42)*-1 -> 0 | H9: =('Country Model'!H42+'Country Model'!AH42)*-1 -> -41243186 | I9: =('Country Model'!I42+'Country Model'!AI42)*-1 -> 0 | J9: =('Country Model'!J42+'Country Model'!AJ42)*-1 -> 0 | K9: =('Country Model'!K42+'Country Model'!AK42)*-1 -> -44597074 | L9: =('Country Model'!L42+'Country Model'!AL42)*-1 -> 0 | ... AD9: =('Country Model'!AD42+'Country Model'!BD42)*-1 -> 0 | AE9: =SUM(E9:AD9) -> -85840260 | AG9: =AG8+1 -> 5
C10: Total costs | E10: =SUM(E7:E9) -> 0 | F10: =SUM(F7:F9) -> 0 | G10: =SUM(G7:G9) -> 0 | H10: =SUM(H7:H9) -> -1.6274607e+08 | I10: =SUM(I7:I9) -> -1.2871853e+08 | J10: =SUM(J7:J9) -> -1.4361351e+08 | K10: =SUM(K7:K9) -> -2.0387061e+08 | L10: =SUM(L7:L9) -> -1.7573065e+08 | ... AD10: =SUM(AD7:AD9) -> -2.2322008e+08 | AE10: =SUM(E10:AD10) -> -4.1507842e+09 | AG10: =AG9+1 -> 6
D11: Benefit: Emergency WASH costs averted | E11: =('Country Model'!E61- 'Country Model'!E81) + ('Country Model'!AE61-'Country Model'!AE81) -> 0 | F11: =('Country Model'!F61- 'Country Model'!F81) + ('Country Model'!AF61-'Country Model'!AF81) -> 0 | G11: =('Country Model'!G61- 'Country Model'!G81) + ('Country Model'!AG61-'Country Model'!AG81) -> 0 | H11: =('Country Model'!H61- 'Country Model'!H81) + ('Country Model'!AH61-'Country Model'!AH81) -> 20916221 | I11: =('Country Model'!I61- 'Country Model'!I81) + ('Country Model'!AI61-'Country Model'!AI81) -> 22026787 | J11: =('Country Model'!J61- 'Country Model'!J81) + ('Country Model'!AJ61-'Country Model'!AJ81) -> 23185116 | K11: =('Country Model'!K61- 'Country Model'!K81) + ('Country Model'!AK61-'Country Model'!AK81) -> 24393181 | L11: =('Country Model'!L61- 'Country Model'!L81) + ('Country Model'!AL61-'Country Model'!AL81) -> 25653038 | ... AD11: =('Country Model'!AD61- 'Country Model'!AD81) + ('Country Model'!BD61-'Country Model'!BD81) -> 48140653 | AE11: =SUM(E11:AD11) -> 7.9267779e+08 | AG11: =AG10+1 -> 7
D12: Benefit: Emergency OCV costs averted | E12: =('Country Model'!E62-'Country Model'!E82)-('Country Model'!AE62-'Country Model'!AE82) -> 0 | F12: =('Country Model'!F62-'Country Model'!F82)-('Country Model'!AF62-'Country Model'!AF82) -> 0 | G12: =('Country Model'!G62-'Country Model'!G82)-('Country Model'!AG62-'Country Model'!AG82) -> 0 | H12: =('Country Model'!H62-'Country Model'!H82)-('Country Model'!AH62-'Country Model'!AH82) -> -1901549.3 | I12: =('Country Model'!I62-'Country Model'!I82)-('Country Model'!AI62-'Country Model'!AI82) -> -1813899.8 | J12: =('Country Model'!J62-'Country Model'!J82)-('Country Model'!AJ62-'Country Model'!AJ82) -> -1826951.1 | K12: =('Country Model'!K62-'Country Model'!K82)-('Country Model'!AK62-'Country Model'!AK82) -> -1721154.3 | L12: =('Country Model'!L62-'Country Model'!L82)-('Country Model'!AL62-'Country Model'!AL82) -> -1731521.2 | ... AD12: =('Country Model'!AD62-'Country Model'!AD82)-('Country Model'!BD62-'Country Model'!BD82) -> -1646911 | AE12: =SUM(E12:AD12) -> -40304848 | AG12: =AG11+1 -> 8
D13: Benefit: Emergency CM costs averted | E13: ='Country Model'!E63-'Country Model'!E83 -> 0 | F13: ='Country Model'!F63-'Country Model'!F83 -> 0 | G13: ='Country Model'!G63-'Country Model'!G83 -> 0 | H13: ='Country Model'!H63-'Country Model'!H83 -> 85930.118 | I13: ='Country Model'!I63-'Country Model'!I83 -> 95666.119 | J13: ='Country Model'!J63-'Country Model'!J83 -> 106070.91 | K13: ='Country Model'!K63-'Country Model'!K83 -> 117183.6 | L13: ='Country Model'!L63-'Country Model'!L83 -> 129045.42 | ... AD13: ='Country Model'!AD63-'Country Model'!AD83 -> 300705.74 | AE13: =SUM(E13:AD13) -> 4423822.5 | AG13: =AG12+1 -> 9
D14: Benefit: Cholera productive time gained | E14: =('Country Model'!E64-'Country Model'!E84)+('Country Model'!AE64-'Country Model'!AE84) -> 0 | F14: =('Country Model'!F64-'Country Model'!F84)+('Country Model'!AF64-'Country Model'!AF84) -> 0 | G14: =('Country Model'!G64-'Country Model'!G84)+('Country Model'!AG64-'Country Model'!AG84) -> 0 | H14: =('Country Model'!H64-'Country Model'!H84)+('Country Model'!AH64-'Country Model'!AH84) -> 197148.82 | I14: =('Country Model'!I64-'Country Model'!I84)+('Country Model'!AI64-'Country Model'!AI84) -> 213329.58 | J14: =('Country Model'!J64-'Country Model'!J84)+('Country Model'!AJ64-'Country Model'!AJ84) -> 230498.96 | K14: =('Country Model'!K64-'Country Model'!K84)+('Country Model'!AK64-'Country Model'!AK84) -> 248711.93 | L14: =('Country Model'!L64-'Country Model'!L84)+('Country Model'!AL64-'Country Model'!AL84) -> 268026.37 | ... AD14: =('Country Model'!AD64-'Country Model'!AD84)+('Country Model'!BD64-'Country Model'!BD84) -> 489017.91 | AE14: =SUM(E14:AD14) -> 8123273.3 | AG14: =AG13+1 -> 10
D15: Benefit: Cholera value of life gained | E15: =('Country Model'!E86-'Country Model'!E90)+('Country Model'!AE86-'Country Model'!AE90) -> 0 | F15: =('Country Model'!F86-'Country Model'!F90)+('Country Model'!AF86-'Country Model'!AF90) -> 0 | G15: =('Country Model'!G86-'Country Model'!G90)+('Country Model'!AG86-'Country Model'!AG90) -> 0 | H15: =('Country Model'!H86-'Country Model'!H90)+('Country Model'!AH86-'Country Model'!AH90) -> 71751620 | I15: =('Country Model'!I86-'Country Model'!I90)+('Country Model'!AI86-'Country Model'!AI90) -> 77636111 | J15: =('Country Model'!J86-'Country Model'!J90)+('Country Model'!AJ86-'Country Model'!AJ90) -> 83793137 | K15: =('Country Model'!K86-'Country Model'!K90)+('Country Model'!AK86-'Country Model'!AK90) -> 90234025 | L15: =('Country Model'!L86-'Country Model'!L90)+('Country Model'!AL86-'Country Model'!AL90) -> 96970570 | ... AD15: =('Country Model'!AD86-'Country Model'!AD90)+('Country Model'!BD86-'Country Model'!BD90) -> 1.735926e+08 | AE15: =SUM(E15:AD15) -> 2.9072903e+09 | AG15: =AG14+1 -> 11
D16: Benefit: Diarrhea treatment costs averted | E16: =('Country Model'!E92-'Country Model'!E93)+('Country Model'!AE92-'Country Model'!AE93) -> 0 | F16: =('Country Model'!F92-'Country Model'!F93)+('Country Model'!AF92-'Country Model'!AF93) -> 0 | G16: =('Country Model'!G92-'Country Model'!G93)+('Country Model'!AG92-'Country Model'!AG93) -> 0 | H16: =('Country Model'!H92-'Country Model'!H93)+('Country Model'!AH92-'Country Model'!AH93) -> 27229869 | I16: =('Country Model'!I92-'Country Model'!I93)+('Country Model'!AI92-'Country Model'!AI93) -> 55762116 | J16: =('Country Model'!J92-'Country Model'!J93)+('Country Model'!AJ92-'Country Model'!AJ93) -> 85643895 | K16: =('Country Model'!K92-'Country Model'!K93)+('Country Model'!AK92-'Country Model'!AK93) -> 1.169239e+08 | L16: =('Country Model'!L92-'Country Model'!L93)+('Country Model'!AL92-'Country Model'!AL93) -> 1.4965243e+08 | ... AD16: =('Country Model'!AD92-'Country Model'!AD93)+('Country Model'!BD92-'Country Model'!BD93) -> 2.1639537e+08 | AE16: =SUM(E16:AD16) -> 4.4021863e+09 | AG16: =AG15+1 -> 12
D17: Benefit: Diarrhea productive time gained | E17: =('Country Model'!E97-'Country Model'!E98)+('Country Model'!AE97-'Country Model'!AE98) -> 0 | F17: =('Country Model'!F97-'Country Model'!F98)+('Country Model'!AF97-'Country Model'!AF98) -> 0 | G17: =('Country Model'!G97-'Country Model'!G98)+('Country Model'!AG97-'Country Model'!AG98) -> 0 | H17: =('Country Model'!H97-'Country Model'!H98)+('Country Model'!AH97-'Country Model'!AH98) -> 947969.75 | I17: =('Country Model'!I97-'Country Model'!I98)+('Country Model'!AI97-'Country Model'!AI98) -> 1966596.5 | J17: =('Country Model'!J97-'Country Model'!J98)+('Country Model'!AJ97-'Country Model'!AJ98) -> 3059979 | K17: =('Country Model'!K97-'Country Model'!K98)+('Country Model'!AK97-'Country Model'!AK98) -> 4232436.8 | L17: =('Country Model'!L97-'Country Model'!L98)+('Country Model'!AL97-'Country Model'!AL98) -> 5488522.2 | ... AD17: =('Country Model'!AD97-'Country Model'!AD98)+('Country Model'!BD97-'Country Model'!BD98) -> 14019061 | AE17: =SUM(E17:AD17) -> 2.076901e+08 | AG17: =AG16+1 -> 13
D18: Benefit: Diarrhea value of life gained | E18: =('Country Model'!E102-'Country Model'!E103)+('Country Model'!AE102-'Country Model'!AE103) -> 0 | F18: =('Country Model'!F102-'Country Model'!F103)+('Country Model'!AF102-'Country Model'!AF103) -> 0 | G18: =('Country Model'!G102-'Country Model'!G103)+('Country Model'!AG102-'Country Model'!AG103) -> 0 | H18: =('Country Model'!H102-'Country Model'!H103)+('Country Model'!AH102-'Country Model'!AH103) -> 1.5424741e+08 | I18: =('Country Model'!I102-'Country Model'!I103)+('Country Model'!AI102-'Country Model'!AI103) -> 1.6064502e+08 | J18: =('Country Model'!J102-'Country Model'!J103)+('Country Model'!AJ102-'Country Model'!AJ103) -> 1.6734276e+08 | K18: =('Country Model'!K102-'Country Model'!K103)+('Country Model'!AK102-'Country Model'!AK103) -> 1.7435633e+08 | L18: =('Country Model'!L102-'Country Model'!L103)+('Country Model'!AL102-'Country Model'!AL103) -> 1.8170229e+08 | ... AD18: =('Country Model'!AD102-'Country Model'!AD103)+('Country Model'!BD102-'Country Model'!BD103) -> 3.4583357e+08 | AE18: =SUM(E18:AD18) -> 5.5329363e+09 | AG18: =AG17+1 -> 14
D19: Benefit: WASH access time savings | E19: =('Country Model'!E107+'Country Model'!E109)+('Country Model'!AE107+'Country Model'!AE109) -> 0 | F19: =('Country Model'!F107+'Country Model'!F109)+('Country Model'!AF107+'Country Model'!AF109) -> 0 | G19: =('Country Model'!G107+'Country Model'!G109)+('Country Model'!AG107+'Country Model'!AG109) -> 0 | H19: =('Country Model'!H107+'Country Model'!H109)+('Country Model'!AH107+'Country Model'!AH109) -> 8039644.6 | I19: =('Country Model'!I107+'Country Model'!I109)+('Country Model'!AI107+'Country Model'!AI109) -> 16644500 | J19: =('Country Model'!J107+'Country Model'!J109)+('Country Model'!AJ107+'Country Model'!AJ109) -> 25844912 | K19: =('Country Model'!K107+'Country Model'!K109)+('Country Model'!AK107+'Country Model'!AK109) -> 35672714 | L19: =('Country Model'!L107+'Country Model'!L109)+('Country Model'!AL107+'Country Model'!AL109) -> 46161294 | ... AD19: =('Country Model'!AD107+'Country Model'!AD109)+('Country Model'!BD107+'Country Model'!BD109) -> 1.2099554e+08 | AE19: =SUM(E19:AD19) -> 1.767964e+09 | AG19: =AG18+1 -> 15
D20: Benefits of OCV Only | L20: =('Country Model'!L86-'Country Model'!L88)+('Country Model'!AL86-'Country Model'!AL88)+L12 -> 73965797 | M20: =('Country Model'!M86-'Country Model'!M88)+('Country Model'!AM86-'Country Model'!AM88)+M12 -> 76042731 | N20: =('Country Model'!N86-'Country Model'!N88)+('Country Model'!AN86-'Country Model'!AN88)+N12 -> 78182641 | O20: =('Country Model'!O86-'Country Model'!O88)+('Country Model'!AO86-'Country Model'!AO88)+O12 -> 80387604 | P20: =('Country Model'!P86-'Country Model'!P88)+('Country Model'!AP86-'Country Model'!AP88)+P12 -> 82659769 | Q20: =('Country Model'!Q86-'Country Model'!Q88)+('Country Model'!AQ86-'Country Model'!AQ88)+Q12 -> 85001360 | R20: =('Country Model'!R86-'Country Model'!R88)+('Country Model'!AR86-'Country Model'!AR88)+R12 -> 87414683 | S20: =('Country Model'!S86-'Country Model'!S88)+('Country Model'!AS86-'Country Model'!AS88)+S12 -> 89902125 | ... AE20: =('Country Model'!AE86-'Country Model'!AE88)+('Country Model'!BE86-'Country Model'!BE88)+AE12 -> 2.3440258e+08 | AG20: =AG19+1 -> 16
D21: Benefits for ramp up of WASH | L21: =IF(Tables!L$5='User Inputs'!$F$9,Tables!L$22*Tables!$L$3,IF(Tables!L5='User Inputs'!$F$9+1,Tables!L22*Tables!$M$3,IF(Tables!L5='User Inputs'!$F$9+2,Tables!L22*Tables!$N$3,IF(Tables!L5='User Inputs'!$F$9+3,Tables!L22*Tables!$O$3,IF(Tables!L5='User Inputs'!$F$9+4,Tables!L22*Tables!$P$3,L22))))) -> 5.042937e+08 | M21: =IF(Tables!M$5='User Inputs'!$F$9,Tables!M$22*Tables!$L$3,IF(Tables!M5='User Inputs'!$F$9+1,Tables!M22*Tables!$M$3,IF(Tables!M5='User Inputs'!$F$9+2,Tables!M22*Tables!$N$3,IF(Tables!M5='User Inputs'!$F$9+3,Tables!M22*Tables!$O$3,IF(Tables!M5='User Inputs'!$F$9+4,Tables!M22*Tables!$P$3,M22))))) -> 5.6712951e+08 | N21: =IF(Tables!N$5='User Inputs'!$F$9,Tables!N$22*Tables!$L$3,IF(Tables!N5='User Inputs'!$F$9+1,Tables!N22*Tables!$M$3,IF(Tables!N5='User Inputs'!$F$9+2,Tables!N22*Tables!$N$3,IF(Tables!N5='User Inputs'!$F$9+3,Tables!N22*Tables!$O$3,IF(Tables!N5='User Inputs'!$F$9+4,Tables!N22*Tables!$P$3,N22))))) -> 6.3452263e+08 | O21: =IF(Tables!O$5='User Inputs'!$F$9,Tables!O$22*Tables!$L$3,IF(Tables!O5='User Inputs'!$F$9+1,Tables!O22*Tables!$M$3,IF(Tables!O5='User Inputs'!$F$9+2,Tables!O22*Tables!$N$3,IF(Tables!O5='User Inputs'!$F$9+3,Tables!O22*Tables!$O$3,IF(Tables!O5='User Inputs'!$F$9+4,Tables!O22*Tables!$P$3,O22))))) -> 6.4946045e+08 | P21: =IF(Tables!P$5='User Inputs'!$F$9,Tables!P$22*Tables!$L$3,IF(Tables!P5='User Inputs'!$F$9+1,Tables!P22*Tables!$M$3,IF(Tables!P5='User Inputs'!$F$9+2,Tables!P22*Tables!$N$3,IF(Tables!P5='User Inputs'!$F$9+3,Tables!P22*Tables!$O$3,IF(Tables!P5='User Inputs'!$F$9+4,Tables!P22*Tables!$P$3,P22))))) -> 66473529 | Q21: =IF(Tables!Q$5='User Inputs'!$F$9,Tables!Q$22*Tables!$L$3,IF(Tables!Q5='User Inputs'!$F$9+1,Tables!Q22*Tables!$M$3,IF(Tables!Q5='User Inputs'!$F$9+2,Tables!Q22*Tables!$N$3,IF(Tables!Q5='User Inputs'!$F$9+3,Tables!Q22*Tables!$O$3,IF(Tables!Q5='User Inputs'!$F$9+4,Tables!Q22*Tables!$P$3,Q22))))) -> 2.0410624e+08 | R21: =IF(Tables!R$5='User Inputs'!$F$9,Tables!R$22*Tables!$L$3,IF(Tables!R5='User Inputs'!$F$9+1,Tables!R22*Tables!$M$3,IF(Tables!R5='User Inputs'!$F$9+2,Tables!R22*Tables!$N$3,IF(Tables!R5='User Inputs'!$F$9+3,Tables!R22*Tables!$O$3,IF(Tables!R5='User Inputs'!$F$9+4,Tables!R22*Tables!$P$3,R22))))) -> 3.4816207e+08 | S21: =IF(Tables!S$5='User Inputs'!$F$9,Tables!S$22*Tables!$L$3,IF(Tables!S5='User Inputs'!$F$9+1,Tables!S22*Tables!$M$3,IF(Tables!S5='User Inputs'!$F$9+2,Tables!S22*Tables!$N$3,IF(Tables!S5='User Inputs'!$F$9+3,Tables!S22*Tables!$O$3,IF(Tables!S5='User Inputs'!$F$9+4,Tables!S22*Tables!$P$3,S22))))) -> 5.344894e+08 | ... AE21: =IF(Tables!AE$5='User Inputs'!$F$9,Tables!AE$22*Tables!$L$3,IF(Tables!AE5='User Inputs'!$F$9+1,Tables!AE22*Tables!$M$3,IF(Tables!AE5='User Inputs'!$F$9+2,Tables!AE22*Tables!$N$3,IF(Tables!AE5='User Inputs'!$F$9+3,Tables!AE22*Tables!$O$3,IF(Tables!AE5='User Inputs'!$F$9+4,Tables!AE22*Tables!$P$3,AE22))))) -> 1.5582987e+10 | AG21: =AG20+1 -> 17
C22: Total benefits | E22: =SUM(E11:E19) -> 0 | F22: =SUM(F11:F19) -> 0 | G22: =SUM(G11:G19) -> 0 | H22: =SUM(H11:H19) -> 2.8151426e+08 | I22: =SUM(I11:I19) -> 3.3317623e+08 | J22: =SUM(J11:J19) -> 3.8737942e+08 | K22: =SUM(K11:K19) -> 4.4445733e+08 | L22: =SUM(L11:L19) -> 5.042937e+08 | ... AD22: =SUM(AD11:AD19) -> 9.181196e+08 | AE22: =SUM(E22:AD22) -> 1.5582987e+10 | AG22: =AG21+1 -> 18
C23: Net Benefits | E23: =E22-E10 -> 0 | F23: =F22-F10 -> 0 | G23: =G22-G10 -> 0 | H23: =H22-H10 -> 4.4426033e+08 | I23: =I22-I10 -> 4.6189476e+08 | J23: =J22-J10 -> 5.3099293e+08 | K23: =K22-K10 -> 6.4832794e+08 | L23: =L22-L10 -> 6.8002435e+08 | ... AD23: =AD22-AD10 -> 1.1413397e+09 | AE23: =SUM(E23:AD23) -> 1.9733771e+10 | AG23: =AG22+1 -> 19
AG24: =AG23+1 -> 20
B25: 2. Population to be reached | AG25: =AG24+1 -> 21
D26: ='Country Model'!C28 -> Population numbers to be reached with Water | H26: ='Country Model'!H28+'Country Model'!AH28 -> 862606.51 | I26: ='Country Model'!I28+'Country Model'!AI28 -> 862606.51 | J26: ='Country Model'!J28+'Country Model'!AJ28 -> 862606.51 | K26: ='Country Model'!K28+'Country Model'!AK28 -> 862606.51 | L26: ='Country Model'!L28+'Country Model'!AL28 -> 862606.51 | M26: ='Country Model'!M28+'Country Model'!AM28 -> 862606.51 | N26: ='Country Model'!N28+'Country Model'!AN28 -> 862606.51 | O26: ='Country Model'!O28+'Country Model'!AO28 -> 256969.2 | ... AD26: ='Country Model'!AD28+'Country Model'!BD28 -> 393658.57 | AE26: =SUM(H26:AD26) -> 11165066 | AG26: =AG25+1 -> 22
D27: ='Country Model'!C29 -> Population numbers to be reached with Sanitation | H27: ='Country Model'!H29+'Country Model'!AH29 -> 1022458.6 | I27: ='Country Model'!I29+'Country Model'!AI29 -> 1022458.6 | J27: ='Country Model'!J29+'Country Model'!AJ29 -> 1022458.6 | K27: ='Country Model'!K29+'Country Model'!AK29 -> 1022458.6 | L27: ='Country Model'!L29+'Country Model'!AL29 -> 1022458.6 | M27: ='Country Model'!M29+'Country Model'!AM29 -> 1022458.6 | N27: ='Country Model'!N29+'Country Model'!AN29 -> 1022458.6 | O27: ='Country Model'!O29+'Country Model'!AO29 -> 256969.2 | ... AD27: ='Country Model'!AD29+'Country Model'!BD29 -> 393658.57 | AE27: =SUM(H27:AD27) -> 12284031 | AG27: =AG26+1 -> 23
D28: ='Country Model'!C30 -> Population numbers to be reached with Hygiene | H28: ='Country Model'!H30+'Country Model'!AH30 -> 1196308.2 | I28: ='Country Model'!I30+'Country Model'!AI30 -> 1196308.2 | J28: ='Country Model'!J30+'Country Model'!AJ30 -> 1196308.2 | K28: ='Country Model'!K30+'Country Model'!AK30 -> 1196308.2 | L28: ='Country Model'!L30+'Country Model'!AL30 -> 1196308.2 | M28: ='Country Model'!M30+'Country Model'!AM30 -> 1196308.2 | N28: ='Country Model'!N30+'Country Model'!AN30 -> 1196308.2 | O28: ='Country Model'!O30+'Country Model'!AO30 -> 256969.2 | ... AD28: ='Country Model'!AD30+'Country Model'!BD30 -> 393658.57 | AE28: =SUM(H28:AD28) -> 13500978 | AG28: =AG27+1 -> 24
D29: ='Country Model'!C31 -> Population numbers to be reached with OCV (with WASH) | H29: ='Country Model'!H31+'Country Model'!AH31 -> 7014147.3 | I29: ='Country Model'!I31+'Country Model'!AI31 -> 0 | J29: ='Country Model'!J31+'Country Model'!AJ31 -> 0 | K29: ='Country Model'!K31+'Country Model'!AK31 -> 7584536.4 | L29: ='Country Model'!L31+'Country Model'!AL31 -> 0 | M29: ='Country Model'!M31+'Country Model'!AM31 -> 0 | N29: ='Country Model'!N31+'Country Model'!AN31 -> 0 | O29: ='Country Model'!O31+'Country Model'!AO31 -> 0 | ... AD29: ='Country Model'!AD31+'Country Model'!BD31 -> 0 | AE29: =SUM(H29:AD29) -> 14598684 | AG29: =AG28+1 -> 25
D30: ='Country Model'!C32 -> Population numbers to be reached with OCV (alone) | H30: ='Country Model'!H32+'Country Model'!AH32 -> 7014147.3 | I30: ='Country Model'!I32+'Country Model'!AI32 -> 0 | J30: ='Country Model'!J32+'Country Model'!AJ32 -> 0 | K30: ='Country Model'!K32+'Country Model'!AK32 -> 7584536.4 | L30: ='Country Model'!L32+'Country Model'!AL32 -> 0 | M30: ='Country Model'!M32+'Country Model'!AM32 -> 0 | N30: ='Country Model'!N32+'Country Model'!AN32 -> 8204428 | O30: ='Country Model'!O32+'Country Model'!AO32 -> 0 | ... AD30: ='Country Model'!AD32+'Country Model'!BD32 -> 0 | AE30: =SUM(H30:AD30) -> 75211091 | AG30: =AG29+1 -> 26
D31: TOTAL | L31: =L30+L28 -> 1196308.2 | M31: =M30+M28 -> 1196308.2 | N31: =N30+N28 -> 9400736.3 | O31: =O30+O28 -> 256969.2 | P31: =P30+P28 -> 264261.75 | Q31: =Q30+Q28 -> 9150263.9 | R31: =R30+R28 -> 279525.89 | S31: =S30+S28 -> 287512.68 | ... AE31: =AE30+AE28 -> 88712069 | AG31: =AG30+1 -> 27
B32: 3a. WASH Total costs by year for increasing coverage - Urban | AF32: ="NPV @ "& ROUND(('User Inputs'!$F$11*100),0) & "%" -> NPV @ 5% | AG32: =AG31+1 -> 28
D33: Water | E33: ='Country Model'!E34+'Country Model'!E38 -> 0 | F33: ='Country Model'!F34+'Country Model'!F38 -> 0 | G33: ='Country Model'!G34+'Country Model'!G38 -> 0 | H33: ='Country Model'!H34+'Country Model'!H38 -> 14669258 | I33: ='Country Model'!I34+'Country Model'!I38 -> 7877719 | J33: ='Country Model'!J34+'Country Model'!J38 -> 8041152 | K33: ='Country Model'!K34+'Country Model'!K38 -> 8215066.5 | L33: ='Country Model'!L34+'Country Model'!L38 -> 8400056.4 | ... AD33: ='Country Model'!AD34+'Country Model'!AD38 -> 13351055 | AE33: =SUM(H33:AD33) -> 2.2413316e+08 | AF33: =NPV(NPV_Country,E33:AD33) -> 1.1027951e+08 | AG33: =AG32+1 -> 29
D34: Sanitation | E34: ='Country Model'!E35+'Country Model'!E39 -> 0 | F34: ='Country Model'!F35+'Country Model'!F39 -> 0 | G34: ='Country Model'!G35+'Country Model'!G39 -> 0 | H34: ='Country Model'!H35+'Country Model'!H39 -> 7180877.8 | I34: ='Country Model'!I35+'Country Model'!I39 -> 7755837.7 | J34: ='Country Model'!J35+'Country Model'!J39 -> 8378388.9 | K34: ='Country Model'!K35+'Country Model'!K39 -> 9051524.6 | L34: ='Country Model'!L35+'Country Model'!L39 -> 9778405.9 | ... AD34: ='Country Model'!AD35+'Country Model'!AD39 -> 14106718 | AE34: =SUM(H34:AD34) -> 2.3267089e+08 | AF34: =NPV(NPV_Country,E34:AD34) -> 1.1226413e+08 | AG34: =AG33+1 -> 30
D35: Hygiene | E35: ='Country Model'!E36+'Country Model'!E40 -> 0 | F35: ='Country Model'!F36+'Country Model'!F40 -> 0 | G35: ='Country Model'!G36+'Country Model'!G40 -> 0 | H35: ='Country Model'!H36+'Country Model'!H40 -> 4684069.7 | I35: ='Country Model'!I36+'Country Model'!I40 -> 6170490.7 | J35: ='Country Model'!J36+'Country Model'!J40 -> 7779947.8 | K35: ='Country Model'!K36+'Country Model'!K40 -> 9520178.9 | L35: ='Country Model'!L36+'Country Model'!L40 -> 11399356 | ... AD35: ='Country Model'!AD36+'Country Model'!AD40 -> 25965111 | AE35: =SUM(H35:AD35) -> 3.7883828e+08 | AF35: =NPV(NPV_Country,E35:AD35) -> 1.7083757e+08 | AG35: =AG34+1 -> 31
AG36: =AG35+1 -> 32
B37: 3b. WASH Total costs by year for increasing coverage - Rural | AG37: =AG36+1 -> 33
D38: Water | E38: ='Country Model'!AE34+'Country Model'!AE38 -> 0 | F38: ='Country Model'!AF34+'Country Model'!AF38 -> 0 | G38: ='Country Model'!AG34+'Country Model'!AG38 -> 0 | H38: ='Country Model'!AH34+'Country Model'!AH38 -> 50269874 | I38: ='Country Model'!AI34+'Country Model'!AI38 -> 54539989 | J38: ='Country Model'!AJ34+'Country Model'!AJ38 -> 59005278 | K38: ='Country Model'!AK34+'Country Model'!AK38 -> 63672579 | L38: ='Country Model'!AL34+'Country Model'!AL38 -> 68548945 | ... AD38: ='Country Model'!BD34+'Country Model'!BD38 -> 72348614 | AE38: =SUM(H38:AD38) -> 1.4259058e+09 | AF38: =NPV(NPV_Country,E38:AD38) -> 7.1243103e+08 | AG38: =AG37+1 -> 34
D39: Sanitation | E39: ='Country Model'!AE35+'Country Model'!AE39 -> 0 | F39: ='Country Model'!AF35+'Country Model'!AF39 -> 0 | G39: ='Country Model'!AG35+'Country Model'!AG39 -> 0 | H39: ='Country Model'!AH35+'Country Model'!AH39 -> 37481752 | I39: ='Country Model'!AI35+'Country Model'!AI39 -> 40868628 | J39: ='Country Model'!AJ35+'Country Model'!AJ39 -> 44413712 | K39: ='Country Model'!AK35+'Country Model'!AK39 -> 48122588 | L39: ='Country Model'!AL35+'Country Model'!AL39 -> 52001016 | ... AD39: ='Country Model'!BD35+'Country Model'!BD39 -> 48693186 | AE39: =SUM(H39:AD39) -> 9.9697004e+08 | AF39: =NPV(NPV_Country,E39:AD39) -> 5.055487e+08 | AG39: =AG38+1 -> 35
D40: Hygiene | E40: ='Country Model'!AE36+'Country Model'!AE40 -> 0 | F40: ='Country Model'!AF36+'Country Model'!AF40 -> 0 | G40: ='Country Model'!AG36+'Country Model'!AG40 -> 0 | H40: ='Country Model'!AH36+'Country Model'!AH40 -> 7217048.5 | I40: ='Country Model'!AI36+'Country Model'!AI40 -> 11505869 | J40: ='Country Model'!AJ36+'Country Model'!AJ40 -> 15995028 | K40: ='Country Model'!AK36+'Country Model'!AK40 -> 20691598 | L40: ='Country Model'!AL36+'Country Model'!AL40 -> 25602874 | ... AD40: ='Country Model'!BD36+'Country Model'!BD40 -> 48755391 | AE40: =SUM(H40:AD40) -> 8.0642584e+08 | AF40: =NPV(NPV_Country,E40:AD40) -> 3.682445e+08 | AG40: =AG39+1 -> 36
AG41: =AG40+1 -> 37
B42: 3d. Distribution of total costs | AG42: =AG41+1 -> 38
...

Sheet Country Model
A1: ='User Inputs'!F5 -> Malawi
A2: =IF($EQI$8="Crisis","Crisis Country","")
